Workbook

Sheet PLANO B
A1: PROGRESSISTAS | C1: PSD | E1: MDB | G1: UB | I1: PL | K1: PT
A2: AGUINALDO | B2: =SUM('APURAÇÃO DOS VOTOS'!B8:Y8) -> 330 | C2: EVERALDO | D2: =SUM('APURAÇÃO DOS VOTOS'!B19:Y19) -> 227 | E2: ALDO | F2: =SUM('APURAÇÃO DOS VOTOS'!B30:Y30) -> 64 | G2: ARILTON | H2: =SUM('APURAÇÃO DOS VOTOS'!B37:Y37) -> 137 | I2: DAURI | J2: =SUM('APURAÇÃO DOS VOTOS'!B44:Y44) -> 192 | K2: LUIZ | L2: =SUM('APURAÇÃO DOS VOTOS'!B51:Y51) -> 20
A3: BRUNO | B3: =SUM('APURAÇÃO DOS VOTOS'!B9:Y9) -> 174 | C3: GUI | D3: =SUM('APURAÇÃO DOS VOTOS'!B20:Y20) -> 366 | E3: BIANCA | F3: =SUM('APURAÇÃO DOS VOTOS'!B31:Y31) -> 317 | G3: GABRIEL | H3: =SUM('APURAÇÃO DOS VOTOS'!B38:Y38) -> 128 | I3: JANAINA | J3: =SUM('APURAÇÃO DOS VOTOS'!B45:Y45) -> 181 | K3: LUCIANA | L3: =SUM('APURAÇÃO DOS VOTOS'!B52:Y52) -> 74
A4: CELINHO | B4: =SUM('APURAÇÃO DOS VOTOS'!B10:Y10) -> 246 | C4: GUTO | D4: =SUM('APURAÇÃO DOS VOTOS'!B21:Y21) -> 66 | E4: DEDI | F4: =SUM('APURAÇÃO DOS VOTOS'!B32:Y32) -> 228 | G4: NANDO | H4: =SUM('APURAÇÃO DOS VOTOS'!B39:Y39) -> 39 | I4: JUBA | J4: =SUM('APURAÇÃO DOS VOTOS'!B46:Y46) -> 78 | K4: ZENON | L4: =SUM('APURAÇÃO DOS VOTOS'!B53:Y53) -> 76
A5: CESINHA | B5: =SUM('APURAÇÃO DOS VOTOS'!B11:Y11) -> 158 | C5: IVOLI | D5: =SUM('APURAÇÃO DOS VOTOS'!B22:Y22) -> 183 | E5: DINHO | F5: =SUM('APURAÇÃO DOS VOTOS'!B33:Y33) -> 167 | G5: PATRICIA | H5: =SUM('APURAÇÃO DOS VOTOS'!B40:Y40) -> 7 | I5: MANECA | J5: =SUM('APURAÇÃO DOS VOTOS'!B47:Y47) -> 38
A6: FABRICIO | B6: =SUM('APURAÇÃO DOS VOTOS'!B12:Y12) -> 511 | C6: JUNINHO | D6: =SUM('APURAÇÃO DOS VOTOS'!B23:Y23) -> 96 | E6: NICE | F6: =SUM('APURAÇÃO DOS VOTOS'!B34:Y34) -> 3 | G6: PRISCILLA | H6: =SUM('APURAÇÃO DOS VOTOS'!B41:Y41) -> 205 | I6: VALDEMAR | J6: =SUM('APURAÇÃO DOS VOTOS'!B48:Y48) -> 19
A7: FRANCIELE | B7: =SUM('APURAÇÃO DOS VOTOS'!B13:Y13) -> 116 | C7: NARA | D7: =SUM('APURAÇÃO DOS VOTOS'!B24:Y24) -> 55 | E7: ZOINHO | F7: =SUM('APURAÇÃO DOS VOTOS'!B35:Y35) -> 260 | G7: TIAGO | H7: =SUM('APURAÇÃO DOS VOTOS'!B42:Y42) -> 167 | I7: VALDIR | J7: =SUM('APURAÇÃO DOS VOTOS'!B49:Y49) -> 121
A8: KARINA | B8: =SUM('APURAÇÃO DOS VOTOS'!B14:Y14) -> 36 | C8: RAQUEL | D8: =SUM('APURAÇÃO DOS VOTOS'!B25:Y25) -> 148
A9: ROBINHO | B9: =SUM('APURAÇÃO DOS VOTOS'!B15:Y15) -> 106 | C9: RONALDO | D9: =SUM('APURAÇÃO DOS VOTOS'!B26:Y26) -> 31
A10: RUANITO | B10: =SUM('APURAÇÃO DOS VOTOS'!B16:Y16) -> 206 | C10: SERGIO | D10: =SUM('APURAÇÃO DOS VOTOS'!B27:Y27) -> 298
A11: VANESSA | B11: =SUM('APURAÇÃO DOS VOTOS'!B17:Y17) -> 285 | C11: TOMAZIA | D11: =SUM('APURAÇÃO DOS VOTOS'!B28:Y28) -> 45
A12: TOTAL | B12: =SUM(B2:B11) -> 2168 | D12: =SUM(D2:D11) -> 1515 | F12: =SUM(F2:F11) -> 1039 | H12: =SUM(H2:H11) -> 683 | J12: =SUM(J2:J11) -> 629 | L12: =SUM(L2:L11) -> 170
A13: QUOCIENTE PARTIDÁRIO | B13: =(B12/C21) -> 3.1450677 | D13: =D12/C21 -> 2.1977756 | F13: =F12/C21 -> 1.5072534 | H13: =H12/C21 -> 0.99081238 | J13: =J12/C21 -> 0.91247582 | L13: =L12/C21 -> 0.24661509
B14: =Int(B13) -> 3 | D14: =INT(D13) -> 2 | F14: =INT(F13) -> 1 | H14: =INT(H13) -> 0 | J14: =INT(J13) -> 0 | L14: =INT(L13) -> 0
A15: CALCULO DAS SOBRAS | B15: =B12/(B14+1) -> 542 | D15: =D12/(D14+1) -> 505 | F15: =F12/(F14+1) -> 519.5 | H15: =H12/(H14+1) -> 683 | J15: =J12/(J14+1) -> 629 | L15: =L12/(L14+1) -> 170
B16: 1 | F16: 0 | H16: 1 | J16: 1 | L16: 0
B17: =B12/((B14+B16)+1) -> 433.6 | D17: =D12/(D14+D16+1) -> 505 | F17: =F12/(F14+F16+1) -> 519.5 | H17: =H12/(H14+H16+1) -> 341.5 | J17: =J12/(J14+J16+1) -> 314.5 | L17: =L12/(L14+L16+1) -> 170
D18: 0 | F18: 0 | H18: 0 | J18: 0 | L18: 0
A20: TOTAL DE VOTOS | C20: =SUM(B12:L12) -> 6204
A21: QUOCIENTE | C21: =C20/9 -> 689.33333
A23: PARTIDO | B23: VAGAS | C23: VAGAS AUTO | E23: PREFEITO
A24: PP | B24: =B14+B16+B18 -> 4 | C24: ='Calculo Magico'!B20 -> 4 | E24: FERNANDA | F24: =SUM('APURAÇÃO DOS VOTOS'!B4:Y4) -> 3000 | G24: =F24/(SUM($F$24:$F$26)) -> 0.47641734
A25: PSD | B25: =D14+D16+D18 -> 2 | C25: ='Calculo Magico'!B21 -> 2 | E25: TIAGO | F25: =SUM('APURAÇÃO DOS VOTOS'!B5:Y5) -> 2710 | G25: =F25/(SUM($F$24:$F$26)) -> 0.43036367
A26: MDB | B26: =F14+F16+F18 -> 1 | C26: ='Calculo Magico'!B22 -> 1 | E26: ISAAC | F26: =SUM('APURAÇÃO DOS VOTOS'!B6:Y6) -> 587 | G26: =F26/(SUM($F$24:$F$26)) -> 0.093218993
A27: UB | B27: =H14+H16+H18 -> 1 | C27: ='Calculo Magico'!B23 -> 1 | E27: TOTAL | F27: =SUM(F24:F26) -> 6297
A28: PL | B28: =J14+J16+J18 -> 1 | C28: ='Calculo Magico'!B24 -> 1
A29: PT | B29: =L14+L16+L18 -> 0 | C29: ='Calculo Magico'!B25 -> 0

Sheet Calculo Magico
A1: PROGRESSISTAS | C1: PSD | E1: MDB | G1: UB | I1: PL | K1: PT
A2: AGUINALDO | B2: =SUM('APURAÇÃO DOS VOTOS'!B8:Y8) -> 330 | C2: EVERALDO | D2: =SUM('APURAÇÃO DOS VOTOS'!B19:Y19) -> 227 | E2: ALDO | F2: =SUM('APURAÇÃO DOS VOTOS'!B30:Y30) -> 64 | G2: ARILTON | H2: =SUM('APURAÇÃO DOS VOTOS'!B37:Y37) -> 137 | I2: DAURI | J2: =SUM('APURAÇÃO DOS VOTOS'!B44:Y44) -> 192 | K2: LUIZ | L2: =SUM('APURAÇÃO DOS VOTOS'!B51:Y51) -> 20
A3: BRUNO | B3: =SUM('APURAÇÃO DOS VOTOS'!B9:Y9) -> 174 | C3: GUI | D3: =SUM('APURAÇÃO DOS VOTOS'!B20:Y20) -> 366 | E3: BIANCA | F3: =SUM('APURAÇÃO DOS VOTOS'!B31:Y31) -> 317 | G3: GABRIEL | H3: =SUM('APURAÇÃO DOS VOTOS'!B38:Y38) -> 128 | I3: JANAINA | J3: =SUM('APURAÇÃO DOS VOTOS'!B45:Y45) -> 181 | K3: LUCIANA | L3: =SUM('APURAÇÃO DOS VOTOS'!B52:Y52) -> 74
A4: CELINHO | B4: =SUM('APURAÇÃO DOS VOTOS'!B10:Y10) -> 246 | C4: GUTO | D4: =SUM('APURAÇÃO DOS VOTOS'!B21:Y21) -> 66 | E4: DEDI | F4: =SUM('APURAÇÃO DOS VOTOS'!B32:Y32) -> 228 | G4: NANDO | H4: =SUM('APURAÇÃO DOS VOTOS'!B39:Y39) -> 39 | I4: JUBA | J4: =SUM('APURAÇÃO DOS VOTOS'!B46:Y46) -> 78 | K4: ZENON | L4: =SUM('APURAÇÃO DOS VOTOS'!B53:Y53) -> 76
A5: CESINHA | B5: =SUM('APURAÇÃO DOS VOTOS'!B11:Y11) -> 158 | C5: IVOLI | D5: =SUM('APURAÇÃO DOS VOTOS'!B22:Y22) -> 183 | E5: DINHO | F5: =SUM('APURAÇÃO DOS VOTOS'!B33:Y33) -> 167 | G5: PATRICIA | H5: =SUM('APURAÇÃO DOS VOTOS'!B40:Y40) -> 7 | I5: MANECA | J5: =SUM('APURAÇÃO DOS VOTOS'!B47:Y47) -> 38
A6: FABRICIO | B6: =SUM('APURAÇÃO DOS VOTOS'!B12:Y12) -> 511 | C6: JUNINHO | D6: =SUM('APURAÇÃO DOS VOTOS'!B23:Y23) -> 96 | E6: NICE | F6: =SUM('APURAÇÃO DOS VOTOS'!B34:Y34) -> 3 | G6: PRISCILLA | H6: =SUM('APURAÇÃO DOS VOTOS'!B41:Y41) -> 205 | I6: VALDEMAR | J6: =SUM('APURAÇÃO DOS VOTOS'!B48:Y48) -> 19
A7: FRANCIELE | B7: =SUM('APURAÇÃO DOS VOTOS'!B13:Y13) -> 116 | C7: NARA | D7: =SUM('APURAÇÃO DOS VOTOS'!B24:Y24) -> 55 | E7: ZOINHO | F7: =SUM('APURAÇÃO DOS VOTOS'!B35:Y35) -> 260 | G7: TIAGO | H7: =SUM('APURAÇÃO DOS VOTOS'!B42:Y42) -> 167 | I7: VALDIR | J7: =SUM('APURAÇÃO DOS VOTOS'!B49:Y49) -> 121
A8: KARINA | B8: =SUM('APURAÇÃO DOS VOTOS'!B14:Y14) -> 36 | C8: RAQUEL | D8: =SUM('APURAÇÃO DOS VOTOS'!B25:Y25) -> 148
A9: ROBINHO | B9: =SUM('APURAÇÃO DOS VOTOS'!B15:Y15) -> 106 | C9: RONALDO | D9: =SUM('APURAÇÃO DOS VOTOS'!B26:Y26) -> 31
A10: RUANITO | B10: =SUM('APURAÇÃO DOS VOTOS'!B16:Y16) -> 206 | C10: SERGIO | D10: =SUM('APURAÇÃO DOS VOTOS'!B27:Y27) -> 298
A11: VANESSA | B11: =SUM('APURAÇÃO DOS VOTOS'!B17:Y17) -> 285 | C11: TOMAZIA | D11: =SUM('APURAÇÃO DOS VOTOS'!B28:Y28) -> 45
A12: TOTAL | B12: =SUM(B2:B11) -> 2168 | D12: =SUM(D2:D11) -> 1515 | F12: =SUM(F2:F11) -> 1039 | H12: =SUM(H2:H11) -> 683 | J12: =SUM(J2:J11) -> 629 | L12: =SUM(L2:L11) -> 170
A13: QUOCIENTE PARTIDÁRIO | B13: =(B12/C17) -> 3.1450677 | D13: =D12/C17 -> 2.1977756 | F13: =F12/C17 -> 1.5072534 | H13: =H12/C17 -> 0.99081238 | J13: =J12/C17 -> 0.91247582 | L13: =L12/C17 -> 0.24661509
B14: =Int(B13) -> 3 | D14: =INT(D13) -> 2 | F14: =INT(F13) -> 1 | H14: =INT(H13) -> 0 | J14: =INT(J13) -> 0 | L14: =INT(L13) -> 0
A16: TOTAL DE VOTOS | C16: =SUM(B12:L12) -> 6204
A17: QUOCIENTE | C17: =C16/9 -> 689.33333
A19: PARTIDO | B19: VAGAS AUTO
A20: PP | B20: =Z40 -> 4 | E20: PREFEITO
A21: PSD | B21: =Z41 -> 2 | E21: FERNANDA | F21: =SUM('APURAÇÃO DOS VOTOS'!B4:Y4) -> 3000 | G21: =F21/(SUM($F$24:$F$28)) -> 0.47641734
A22: MDB | B22: =Z42 -> 1 | E22: TIAGO | F22: =SUM('APURAÇÃO DOS VOTOS'!B5:Y5) -> 2710 | G22: =F22/(SUM($F$24:$F$28)) -> 0.43036367
A23: UB | B23: =Z43 -> 1 | E23: ISAAC | F23: =SUM('APURAÇÃO DOS VOTOS'!B6:Y6) -> 587 | G23: =F23/(SUM($F$24:$F$28)) -> 0.093218993
A24: PL | B24: =Z44 -> 1 | E24: TOTAL | F24: =SUM(F21:F23) -> 6297 | N24: TOTAL DE VOTOS | O24: =SUM(B16:L16) -> 6204
A25: PT | B25: =Z45 -> 0 | N25: QUOCIENTE PARTIDÁRIO | O25: =Int((B16/($O$24/9))) -> 0 | P25: =Int((D16/($O$24/9))) -> 0 | Q25: =Int((F16/($O$24/9))) -> 0 | R25: =Int((H16/($O$24/9))) -> 0 | S25: =Int((J16/($O$24/9))) -> 0 | T25: =Int((L16/($O$24/9))) -> 0
O27: PP | P27: PSD | Q27: MDB | R27: UB | S27: PL | T27: PT
A28: VEREADORES MAIS VOTADOS | D28: VEREADORES MAIS VOTADOS POR PARTIDO | N28: 1 | O28: =$B$12/($O$21+N28) -> 2168 | P28: =$D$12/($P$21+N28) -> 1515 | Q28: =$F$12/($Q$21+N28) -> 1039 | R28: =$H$12/($R$21+N28) -> 683 | S28: =$J$12/($S$21+N28) -> 629 | T28: =$L$12/($T$21+N28) -> 170
A29: =IFERROR(__xludf.DUMMYFUNCTION("SORT(ARRAYFORMULA(FLATTEN({ A2:A11&"" "" &B2:B11&"" ""&""- PROGRESSISTAS""; C2:C11&"" "" &D2:D11&"" ""&""- PSD""; E2:E11&"" "" &F2:F11&"" ""&""- MDB""; G2:G11&"" "" &H2:H11&"" ""&""- UB""; I2:I11&"" "" &J2:J11&"" ""&""- PL""; K2:K11&"" "" &L2:"&"L11&"" ""&""- PT"" })), ARRAYFORMULA(FLATTEN({ B2:B11;D2:D11;F2:F11;H2:H11;J2:J11;L2:L11 })), FALSE)"),"FABRICIO 511 - PROGRESSISTAS") -> FABRICIO 511 - PROGRESSISTAS | D29: =A1 -> PROGRESSISTAS | E29: =C1 -> PSD | F29: =E1 -> MDB | G29: =G1 -> UB | H29: =I1 -> PL | I29: =K1 -> PT | N29: 2 | O29: =$B$12/($O$21+N29) -> 1084 | P29: =$D$12/($P$21+N29) -> 757.5 | Q29: =$F$12/($Q$21+N29) -> 519.5 | R29: =$H$12/($R$21+N29) -> 341.5 | S29: =$J$12/($S$21+N29) -> 314.5 | T29: =$L$12/($T$21+N29) -> 85
A30: =IFERROR(__xludf.DUMMYFUNCTION("""COMPUTED_VALUE"""),"GUI 366 - PSD") -> GUI 366 - PSD | D30: {=IF(B20>0, SORT(A2:A11 & " " & B2:B11, B2:B11, FALSE) , "")} -> FABRICIO 511 | E30: {=IF(B21>0, SORT(C2:C11 & " " & D2:D11, D2:D11, FALSE) , "")} -> GUI 366 | F30: {=IF(B22>0, SORT(E2:E11 & " " & F2:F11, F2:F11, FALSE) , "")} -> BIANCA 317 | G30: {=IF(B23>0, SORT(G2:G11 & " " & H2:H11, H2:H11, FALSE) , "Não Há")} -> PRISCILLA 205 | H30: {=IF(B24>0, SORT(I2:I11 & " " & J2:J11, J2:J11, FALSE) , "Não Há")} -> DAURI 192 | I30: {=IF(B25>0, SORT(K2:K11 & " " & L2:L11, L2:L11, FALSE) , "Não Há")} -> Não Há | N30: 3 | O30: =$B$12/($O$21+N30) -> 722.66667 | P30: =$D$12/($P$21+N30) -> 505 | Q30: =$F$12/($Q$21+N30) -> 346.33333 | R30: =$H$12/($R$21+N30) -> 227.66667 | S30: =$J$12/($S$21+N30) -> 209.66667 | T30: =$L$12/($T$21+N30) -> 56.666667
A31: =IFERROR(__xludf.DUMMYFUNCTION("""COMPUTED_VALUE"""),"AGUINALDO 330 - PROGRESSISTAS") -> AGUINALDO 330 - PROGRESSISTAS | D31: AGUINALDO 330 | E31: SERGIO 298 | N31: 4 | O31: =$B$12/($O$21+N31) -> 542 | P31: =$D$12/($P$21+N31) -> 378.75 | Q31: =$F$12/($Q$21+N31) -> 259.75 | R31: =$H$12/($R$21+N31) -> 170.75 | S31: =$J$12/($S$21+N31) -> 157.25 | T31: =$L$12/($T$21+N31) -> 42.5
A32: =IFERROR(__xludf.DUMMYFUNCTION("""COMPUTED_VALUE"""),"BIANCA 317 - MDB") -> BIANCA 317 - MDB | D32: VANESSA 285 | N32: 5 | O32: =$B$12/($O$21+N32) -> 433.6 | P32: =$D$12/($P$21+N32) -> 303 | Q32: =$F$12/($Q$21+N32) -> 207.8 | R32: =$H$12/($R$21+N32) -> 136.6 | S32: =$J$12/($S$21+N32) -> 125.8 | T32: =$L$12/($T$21+N32) -> 34
A33: =IFERROR(__xludf.DUMMYFUNCTION("""COMPUTED_VALUE"""),"SERGIO 298 - PSD") -> SERGIO 298 - PSD | D33: CELINHO 246 | N33: 6 | O33: =$B$12/($O$21+N33) -> 361.33333 | P33: =$D$12/($P$21+N33) -> 252.5 | Q33: =$F$12/($Q$21+N33) -> 173.16667 | R33: =$H$12/($R$21+N33) -> 113.83333 | S33: =$J$12/($S$21+N33) -> 104.83333 | T33: =$L$12/($T$21+N33) -> 28.333333
A34: =IFERROR(__xludf.DUMMYFUNCTION("""COMPUTED_VALUE"""),"VANESSA 285 - PROGRESSISTAS") -> VANESSA 285 - PROGRESSISTAS | N34: 7 | O34: =$B$12/($O$21+N34) -> 309.71429 | P34: =$D$12/($P$21+N34) -> 216.42857 | Q34: =$F$12/($Q$21+N34) -> 148.42857 | R34: =$H$12/($R$21+N34) -> 97.571429 | S34: =$J$12/($S$21+N34) -> 89.857143 | T34: =$L$12/($T$21+N34) -> 24.285714
A35: =IFERROR(__xludf.DUMMYFUNCTION("""COMPUTED_VALUE"""),"ZOINHO 260 - MDB") -> ZOINHO 260 - MDB | N35: 8 | O35: =$B$12/($O$21+N35) -> 271 | P35: =$D$12/($P$21+N35) -> 189.375 | Q35: =$F$12/($Q$21+N35) -> 129.875 | R35: =$H$12/($R$21+N35) -> 85.375 | S35: =$J$12/($S$21+N35) -> 78.625 | T35: =$L$12/($T$21+N35) -> 21.25
A36: =IFERROR(__xludf.DUMMYFUNCTION("""COMPUTED_VALUE"""),"CELINHO 246 - PROGRESSISTAS") -> CELINHO 246 - PROGRESSISTAS | N36: 9 | O36: =$B$12/($O$21+N36) -> 240.88889 | P36: =$D$12/($P$21+N36) -> 168.33333 | Q36: =$F$12/($Q$21+N36) -> 115.44444 | R36: =$H$12/($R$21+N36) -> 75.888889 | S36: =$J$12/($S$21+N36) -> 69.888889 | T36: =$L$12/($T$21+N36) -> 18.888889
A37: =IFERROR(__xludf.DUMMYFUNCTION("""COMPUTED_VALUE"""),"DEDI 228 - MDB") -> DEDI 228 - MDB
A38: =IFERROR(__xludf.DUMMYFUNCTION("""COMPUTED_VALUE"""),"EVERALDO 227 - PSD") -> EVERALDO 227 - PSD | R38: 1 | S38: 2 | T38: 3 | U38: 4 | V38: 5 | W38: 6 | X38: 7 | Y38: 8
A39: =IFERROR(__xludf.DUMMYFUNCTION("""COMPUTED_VALUE"""),"RUANITO 206 - PROGRESSISTAS") -> RUANITO 206 - PROGRESSISTAS | O39: Partido | P39: Quociente Partidario | Q39: Sobras 1 | R39: Sobras 2 | S39: Sobras 3 | T39: Sobras 4 | U39: Sobras 5 | V39: Sobras 6 | W39: Sobras 7 | X39: Sobras 8 | Y39: Sobras 9 | Z39: Total
A40: =IFERROR(__xludf.DUMMYFUNCTION("""COMPUTED_VALUE"""),"PRISCILLA 205 - UB") -> PRISCILLA 205 - UB | O40: PP | P40: =O25 -> 0 | Q40: =IF(COUNTIF($O$28:$O$36, IFERROR(LARGE($O$28:$T$36, $P$47-Q38), 0)) > 0, 1, 0) -> 1 | R40: =IF(COUNTIF($O$28:$O$36, IFERROR(LARGE($O$28:$T$36, $P$47-R38), 0)) > 0, 1, 0) -> 0 | S40: =IF(COUNTIF($O$28:$O$36, IFERROR(LARGE($O$28:$T$36, $P$47-S38), 0)) > 0, 1, 0) -> 0 | T40: =IF(COUNTIF($O$28:$O$36, IFERROR(LARGE($O$28:$T$36, $P$47-T38), 0)) > 0, 1, 0) -> 1 | U40: =IF(COUNTIF($O$28:$O$36, IFERROR(LARGE($O$28:$T$36, $P$47-U38), 0)) > 0, 1, 0) -> 0 | V40: =IF(COUNTIF($O$28:$O$36, IFERROR(LARGE($O$28:$T$36, $P$47-V38), 0)) > 0, 1, 0) -> 0 | W40: =IF(COUNTIF($O$28:$O$36, IFERROR(LARGE($O$28:$T$36, $P$47-W38), 0)) > 0, 1, 0) -> 1 | X40: =IF(COUNTIF($O$28:$O$36, IFERROR(LARGE($O$28:$T$36, $P$47-X38), 0)) > 0, 1, 0) -> 0 | Y40: =IF(COUNTIF($O$28:$O$36, IFERROR(LARGE($O$28:$T$36, $P$47-Y38), 0)) > 0, 1, 0) -> 1 | Z40: =SUM(P40:Y40) -> 4
A41: =IFERROR(__xludf.DUMMYFUNCTION("""COMPUTED_VALUE"""),"DAURI 192 - PL") -> DAURI 192 - PL | O41: PSD | P41: =P25 -> 0 | Q41: =IF(COUNTIF($P$28:$P$36, IFERROR(LARGE($O$28:$T$36, $P$47-Q38), 0)) > 0, 1, 0) -> 0 | R41: =IF(COUNTIF($P$28:$P$36, IFERROR(LARGE($O$28:$T$36, $P$47-R38), 0)) > 0, 1, 0) -> 0 | S41: =IF(COUNTIF($P$28:$P$36, IFERROR(LARGE($O$28:$T$36, $P$47-S38), 0)) > 0, 1, 0) -> 0 | T41: =IF(COUNTIF($P$28:$P$36, IFERROR(LARGE($O$28:$T$36, $P$47-T38), 0)) > 0, 1, 0) -> 0 | U41: =IF(COUNTIF($P$28:$P$36, IFERROR(LARGE($O$28:$T$36, $P$47-U38), 0)) > 0, 1, 0) -> 1 | V41: =IF(COUNTIF($P$28:$P$36, IFERROR(LARGE($O$28:$T$36, $P$47-V38), 0)) > 0, 1, 0) -> 0 | W41: =IF(COUNTIF($P$28:$P$36, IFERROR(LARGE($O$28:$T$36, $P$47-W38), 0)) > 0, 1, 0) -> 0 | X41: =IF(COUNTIF($P$28:$P$36, IFERROR(LARGE($O$28:$T$36, $P$47-X38), 0)) > 0, 1, 0) -> 1 | Y41: =IF(COUNTIF($P$28:$P$36, IFERROR(LARGE($O$28:$T$36, $P$47-Y38), 0)) > 0, 1, 0) -> 0 | Z41: =SUM(P41:Y41) -> 2
A42: =IFERROR(__xludf.DUMMYFUNCTION("""COMPUTED_VALUE"""),"IVOLI 183 - PSD") -> IVOLI 183 - PSD | O42: MDB | P42: =Q25 -> 0 | Q42: =IF(COUNTIF($Q$28:$Q$36, IFERROR(LARGE($O$28:$T$36, $P$47-Q38), 0)) > 0, 1, 0) -> 0 | R42: =IF(COUNTIF($Q$28:$Q$36, IFERROR(LARGE($O$28:$T$36, $P$47-R38), 0)) > 0, 1, 0) -> 0 | S42: =IF(COUNTIF($Q$28:$Q$36, IFERROR(LARGE($O$28:$T$36, $P$47-S38), 0)) > 0, 1, 0) -> 0 | T42: =IF(COUNTIF($Q$28:$Q$36, IFERROR(LARGE($O$28:$T$36, $P$47-T38), 0)) > 0, 1, 0) -> 0 | U42: =IF(COUNTIF($Q$28:$Q$36, IFERROR(LARGE($O$28:$T$36, $P$47-U38), 0)) > 0, 1, 0) -> 0 | V42: =IF(COUNTIF($Q$28:$Q$36, IFERROR(LARGE($O$28:$T$36, $P$47-V38), 0)) > 0, 1, 0) -> 1 | W42: =IF(COUNTIF($Q$28:$Q$36, IFERROR(LARGE($O$28:$T$36, $P$47-W38), 0)) > 0, 1, 0) -> 0 | X42: =IF(COUNTIF($Q$28:$Q$36, IFERROR(LARGE($O$28:$T$36, $P$47-X38), 0)) > 0, 1, 0) -> 0 | Y42: =IF(COUNTIF($Q$28:$Q$36, IFERROR(LARGE($O$28:$T$36, $P$47-Y38), 0)) > 0, 1, 0) -> 0 | Z42: =SUM(P42:Y42) -> 1
A43: =IFERROR(__xludf.DUMMYFUNCTION("""COMPUTED_VALUE"""),"JANAINA 181 - PL") -> JANAINA 181 - PL | O43: UB | P43: =R25 -> 0 | Q43: =IF(COUNTIF($R$28:$R$36, IFERROR(LARGE($O$28:$T$36, $P$47-Q38), 0)) > 0, 1, 0) -> 0 | R43: =IF(COUNTIF($R$28:$R$36, IFERROR(LARGE($O$28:$T$36, $P$47-R38), 0)) > 0, 1, 0) -> 0 | S43: =IF(COUNTIF($R$28:$R$36, IFERROR(LARGE($O$28:$T$36, $P$47-S38), 0)) > 0, 1, 0) -> 1 | T43: =IF(COUNTIF($R$28:$R$36, IFERROR(LARGE($O$28:$T$36, $P$47-T38), 0)) > 0, 1, 0) -> 0 | U43: =IF(COUNTIF($R$28:$R$36, IFERROR(LARGE($O$28:$T$36, $P$47-U38), 0)) > 0, 1, 0) -> 0 | V43: =IF(COUNTIF($R$28:$R$36, IFERROR(LARGE($O$28:$T$36, $P$47-V38), 0)) > 0, 1, 0) -> 0 | W43: =IF(COUNTIF($R$28:$R$36, IFERROR(LARGE($O$28:$T$36, $P$47-W38), 0)) > 0, 1, 0) -> 0 | X43: =IF(COUNTIF($R$28:$R$36, IFERROR(LARGE($O$28:$T$36, $P$47-X38), 0)) > 0, 1, 0) -> 0 | Y43: =IF(COUNTIF($R$28:$R$36, IFERROR(LARGE($O$28:$T$36, $P$47-Y38), 0)) > 0, 1, 0) -> 0 | Z43: =SUM(P43:Y43) -> 1
...

Sheet APURAÇÃO DOS VOTOS
A1: APURAÇÃO DOS VOTOS | B1: S E Ç Ã O
B2: CENTRO | J2: SOROCABA | L2: RIBEIRÃO | N2: FREITAS | Q2: M. AGUDO | R2: PENHA | Y2: AREIAS
B3: 1 | C3: 2 | D3: 3 | E3: 4 | F3: 5 | G3: 6 | H3: 7 | I3: 218 | J3: 8 | K3: 9 | L3: 10 | M3: 11 | N3: 12 | O3: 13 | P3: 14 | Q3: 15 | R3: 16 | S3: 17 | T3: 18 | U3: 19 | V3: 20 | W3: 21 | X3: 22 | Y3: 25
A4: FERNANDA | B4: 157 | C4: 161 | D4: 153 | E4: 139 | F4: 154 | G4: 145 | H4: 142 | I4: 54 | J4: 103 | K4: 69 | L4: 98 | M4: 108 | N4: 141 | O4: 123 | P4: 114 | Q4: 99 | R4: 129 | S4: 141 | T4: 138 | U4: 120 | V4: 120 | W4: 136 | X4: 151 | Y4: 105
A5: TIAGO | B5: 140 | C5: 128 | D5: 124 | E5: 144 | F5: 148 | G5: 135 | H5: 144 | I5: 87 | J5: 116 | K5: 62 | L5: 76 | M5: 66 | N5: 116 | O5: 153 | P5: 141 | Q5: 128 | R5: 93 | S5: 96 | T5: 94 | U5: 108 | V5: 113 | W5: 94 | X5: 86 | Y5: 118
A6: ISAAC | B6: 42 | C6: 32 | D6: 42 | E6: 40 | F6: 33 | G6: 27 | H6: 42 | I6: 7 | J6: 28 | K6: 19 | L6: 20 | M6: 23 | N6: 35 | O6: 29 | P6: 40 | Q6: 39 | R6: 9 | S6: 4 | T6: 5 | U6: 4 | V6: 7 | W6: 9 | X6: 4 | Y6: 47
A7: PP | P7: 5 | T7: 2 | Y7: 1
A8: AGUINALDO | B8: 13 | C8: 14 | D8: 18 | E8: 8 | F8: 13 | G8: 10 | H8: 9 | I8: 1 | J8: 6 | K8: 2 | L8: 17 | M8: 31 | N8: 62 | O8: 48 | P8: 33 | Q8: 14 | R8: 2 | S8: 7 | T8: 6 | U8: 4 | V8: 4 | W8: 2 | X8: 2 | Y8: 4
A9: BRUNO | B9: 14 | C9: 12 | D9: 10 | E9: 16 | F9: 24 | G9: 19 | H9: 22 | I9: 23 | J9: 8 | K9: 3 | M9: 1 | N9: 4 | O9: 2 | P9: 6 | Q9: 3 | S9: 3 | U9: 2 | V9: 1 | Y9: 1
A10: CELINHO | B10: 4 | C10: 3 | D10: 4 | E10: 10 | F10: 4 | G10: 2 | H10: 1 | I10: 3 | J10: 3 | K10: 2 | M10: 1 | N10: 4 | O10: 3 | P10: 4 | R10: 26 | S10: 29 | T10: 29 | U10: 23 | V10: 31 | W10: 25 | X10: 31 | Y10: 4
A11: CESINHA | B11: 6 | C11: 6 | D11: 7 | E11: 6 | F11: 5 | G11: 9 | H11: 5 | I11: 4 | J11: 1 | M11: 2 | O11: 4 | P11: 3 | Q11: 4 | R11: 10 | S11: 15 | U11: 14 | V11: 39 | W11: 11 | X11: 7
A12: FABRICIO | B12: =22+62 -> 84 | C12: 25 | D12: 21 | E12: 23 | F12: 24 | G12: 20 | H12: 32 | I12: 6 | J12: 22 | K12: 7 | L12: 6 | M12: 7 | N12: 6 | O12: 9 | P12: 17 | Q12: 7 | R12: 16 | S12: 29 | T12: 29 | U12: 31 | V12: 15 | W12: 21 | X12: 30 | Y12: 24
A13: FRANCIELE | B13: 2 | C13: 3 | D13: 1 | E13: 2 | F13: 4 | G13: 1 | H13: 1 | I13: 2 | J13: 1 | L13: 3 | M13: 1 | N13: 1 | O13: 8 | P13: 4 | Q13: 5 | R13: 17 | S13: 11 | T13: 13 | U13: 12 | V13: 3 | W13: 11 | X13: 10
A14: KARINA | B14: 1 | F14: 1 | G14: 1 | H14: 1 | J14: 1 | L14: 13 | M14: 11 | N14: 2 | P14: 2 | Q14: 1 | W14: 1 | Y14: 1
A15: ROBINHO | B15: 3 | C15: 7 | D15: 6 | E15: 5 | F15: 6 | G15: 1 | H15: 7 | I15: 5 | J15: 3 | K15: 2 | L15: 8 | M15: 6 | N15: 2 | O15: 3 | Q15: 1 | R15: 8 | S15: 3 | T15: 6 | U15: 5 | V15: 5 | W15: 6 | X15: 7 | Y15: 1
A16: RUANITO | B16: 19 | C16: 18 | D16: 9 | E16: 7 | F16: 12 | G16: 28 | H16: 18 | J16: 3 | K16: 3 | L16: 7 | M16: 4 | N16: 7 | O16: 3 | P16: 5 | Q16: 5 | R16: 9 | S16: 3 | T16: 6 | U16: 5 | V16: 6 | W16: 7 | X16: 6 | Y16: 16
A17: VANESSA | B17: 21 | C17: 17 | D17: 14 | E17: 20 | F17: 23 | G17: 12 | H17: 21 | I17: 3 | J17: 3 | K17: 1 | L17: 14 | M17: 14 | N17: 16 | O17: 27 | P17: 18 | Q17: 5 | R17: 7 | S17: 5 | T17: 7 | U17: 5 | V17: 8 | W17: 3 | X17: 9 | Y17: 12
A18: PSD
A19: EVERALDO | B19: 3 | C19: 4 | D19: 6 | E19: 6 | F19: 8 | G19: 3 | H19: 5 | J19: 4 | K19: 2 | L19: 4 | M19: 5 | N19: 4 | O19: 8 | P19: 3 | Q19: 17 | R19: 18 | S19: 18 | T19: 21 | U19: 16 | V19: 19 | W19: 23 | X19: 27 | Y19: 3
A20: GUI | B20: =24+16 -> 40 | C20: 41 | D20: 31 | E20: 23 | F20: 19 | G20: 20 | H20: 30 | I20: 2 | J20: 21 | K20: 17 | L20: 2 | M20: 1 | N20: 14 | O20: 23 | P20: 19 | Q20: 10 | R20: 5 | S20: 11 | T20: 6 | U20: 3 | V20: 4 | W20: 5 | X20: 5 | Y20: 14
A21: GUTO | B21: 4 | C21: 6 | D21: 7 | E21: 2 | F21: 1 | G21: 1 | H21: 6 | I21: 1 | J21: 2 | K21: 2 | L21: 3 | M21: 5 | N21: 2 | O21: 3 | P21: 5 | Q21: 1 | R21: 2 | S21: 2 | U21: 1 | V21: 1 | W21: 3 | X21: 1 | Y21: 5
A22: IVOLI | B22: 10 | C22: 13 | D22: 12 | E22: 15 | F22: 16 | G22: 8 | H22: 10 | I22: 4 | J22: 4 | K22: 1 | L22: 5 | M22: 2 | N22: 7 | O22: 9 | P22: 9 | Q22: 31 | R22: 2 | S22: 1 | T22: 1 | U22: 1 | V22: 3 | W22: 2 | X22: 1 | Y22: 16
A23: JUNINHO | B23: 2 | C23: 2 | D23: 5 | F23: 3 | G23: 2 | I23: 2 | J23: 1 | K23: 3 | L23: 13 | M23: 18 | N23: 1 | O23: 3 | P23: 3 | Q23: 1 | R23: 7 | S23: 1 | U23: 4 | V23: 3 | W23: 7 | X23: 5 | Y23: 10
A24: NARA | B24: 4 | C24: 5 | D24: 1 | E24: 6 | G24: 7 | H24: 3 | I24: 1 | J24: 4 | M24: 1 | N24: 1 | P24: 1 | Q24: 7 | W24: 1 | Y24: 13
A25: RAQUEL | B25: 13 | C25: 11 | D25: 11 | E25: 11 | F25: 13 | G25: 10 | H25: 8 | I25: 4 | J25: 10 | K25: 3 | L25: 1 | M25: 7 | N25: 9 | O25: 5 | P25: 8 | Q25: 3 | R25: 3 | S25: 1 | U25: 2 | V25: 4 | X25: 1 | Y25: 10
A26: RONALDO | B26: 3 | C26: 2 | D26: 3 | E26: 2 | F26: 3 | G26: 2 | H26: 3 | I26: 2 | K26: 1 | R26: 1 | U26: 1 | X26: 1 | Y26: 7
A27: SERGIO | B27: 26 | C27: 17 | D27: 23 | E27: 19 | F27: 17 | G27: 24 | H27: 22 | I27: 14 | J27: 22 | K27: 22 | M27: 2 | N27: 4 | O27: 6 | P27: 13 | Q27: 7 | R27: 7 | S27: 7 | T27: 10 | U27: 9 | V27: 3 | W27: 10 | X27: 1 | Y27: 13
A28: TOMAZIA | B28: 1 | D28: 1 | G28: 1 | H28: 1 | R28: 6 | S28: 2 | T28: 8 | U28: 3 | V28: 8 | W28: 9 | X28: 5
A29: MDB | I29: 1
A30: ALDO | B30: 2 | D30: 1 | E30: 3 | F30: 2 | H30: 1 | L30: 23 | M30: 16 | N30: 2 | O30: 1 | P30: 2 | Q30: 4 | S30: 4 | T30: 2 | W30: 1
A31: BIANCA | B31: 10 | C31: 14 | D31: 8 | E31: 20 | F31: 12 | G31: 20 | H31: 16 | I31: 17 | J31: 29 | K31: 21 | L31: 14 | M31: 11 | N31: 11 | O31: 12 | P31: 14 | Q31: 12 | R31: 8 | S31: 15 | T31: 8 | U31: 4 | V31: 6 | W31: 12 | X31: 9 | Y31: 14
A32: DEDI | B32: 18 | C32: 21 | D32: 20 | E32: 21 | F32: 26 | G32: 17 | H32: 16 | I32: 11 | J32: 7 | K32: 8 | L32: 10 | M32: 8 | N32: 5 | O32: 5 | P32: 9 | Q32: 2 | S32: 1 | T32: 1 | U32: 4 | V32: 6 | W32: 1 | X32: 3 | Y32: 8
A33: DINHO | B33: 9 | C33: 10 | D33: 6 | E33: 12 | F33: 11 | G33: 4 | H33: 10 | I33: 2 | J33: 45 | K33: 20 | L33: 6 | M33: 2 | N33: 4 | O33: 4 | P33: 6 | Q33: 3 | R33: 2 | S33: 1 | T33: 3 | U33: 2 | V33: 1 | W33: 1 | X33: 1 | Y33: 2
A34: NICE | E34: 1 | G34: 1 | S34: 1
A35: ZOINHO | B35: 12 | C35: 11 | D35: 14 | E35: 9 | F35: 15 | G35: 19 | H35: 10 | I35: 8 | J35: 10 | K35: 4 | L35: 2 | M35: 1 | N35: 17 | O35: 29 | P35: 15 | Q35: 7 | R35: 8 | S35: 5 | T35: 10 | U35: 7 | V35: 11 | W35: 12 | X35: 7 | Y35: 17
A36: UB
A37: ARILTON | B37: 6 | C37: 7 | D37: 7 | E37: 5 | F37: 4 | G37: 4 | H37: 5 | I37: 2 | J37: 2 | L37: 4 | M37: 8 | N37: 29 | O37: 7 | P37: 24 | Q37: 9 | R37: 1 | V37: 1 | Y37: 12
A38: GABRIEL | B38: 11 | C38: 9 | D38: 9 | E38: 8 | F38: 10 | G38: 7 | H38: 5 | I38: 2 | J38: 6 | K38: 4 | M38: 2 | N38: 12 | O38: 16 | P38: 8 | Q38: 6 | R38: 4 | S38: 1 | U38: 1 | V38: 2 | W38: 2 | X38: 2 | Y38: 1
A39: NANDO | B39: 6 | C39: 2 | D39: 2 | E39: 2 | F39: 4 | G39: 4 | H39: 3 | I39: 1 | J39: 1 | L39: 1 | M39: 2 | N39: 2 | O39: 2 | P39: 1 | Q39: 3 | W39: 1 | X39: 1 | Y39: 1
A40: PATRICIA | B40: 2 | C40: 1 | D40: 1 | G40: 1 | H40: 1 | J40: 1
...
